Workbook

Sheet Raw Data
A1: RAW DATA
C21: Table 1 | E21: Table 2 | G21: Table 3
C23: Sales_Data | E23: Product_Master | G23: Custumer_Master

Sheet Sales_data
A1: Order_ID | B1: Customer_ID | C1: Product_ID | D1: Order_Date | E1: Delivery_Date | F1: Customer_Name | G1: Gender | H1: DOB | I1: City | J1: Region | K1: Category | L1: Product_Name | M1: Quantity | N1: Unit_Price | O1: Discount_% | P1: Sales | Q1: Rating | R1: Payment_Mode | S1: Salesperson | T1: Email | U1: Phone | V1: Order_Status
A2: ORD10001 | B2: C008 | C2: P202 | D2: 18/09/2025 | E2: 22/09/2025 | F2: Kavya Nair | G2: Female | H2: 01/08/1976 | I2: Hyderabad | J2: South | K2: Home Appliances | L2: Iron | M2: 4 | N2: 2200 | O2: 10 | P2: 7920 | Q2: 4 | R2: Cash | S2: Ritika | T2: KAvya.nair@company.com | U2: 9431429797 | V2: Completed
A3: ORD10002 | B3: C008 | C3: P104 | D3: 27/04/2025 | E3: 04/05/2025 | F3: Kavya Nair | G3: Female | H3: 16/10/2000 | I3: Delhi | J3: North | K3: Electronics | L3: Monitor | M3: 17 | N3: 12000 | O3: 10 | P3: 183600 | Q3: 1 | R3: NetBanking | S3: Rahul | T3: kavya.nair@company.com | U3: 9129865339 | V3: Completed
A4: ORD10003 | B4: C010 | C4: P101 | D4: 03/09/2025 | E4: 14/09/2025 | F4: pooja shah | G4: Female | H4: 16/09/1994 | I4: Bengaluru | J4: South | K4: Electronics | L4: Laptop | M4: 5 | N4: 55000 | O4: 5 | P4: 261250 | Q4: 3 | R4: NetBanking | S4: Aisha | T4: pooja.shah@company.com | U4: 9380975626 | V4: Pending
A5: ORD10002 | B5: C008 | C5: P202 | D5: 21/03/2026 | E5: 02/04/2026 | F5: Kavya Nair | G5: Female | H5: 07/03/2004 | I5: Bengaluru | J5: South | K5: Home Appliances | L5: Iron | M5: 5 | N5: 2200 | O5: 5 | P5: 10450 | Q5: 5 | R5: NetBanking | S5: Aisha | T5: kavya.nair@company.com | U5: 9600261125 | V5: Cancelled
A6: ORD10005 | B6: C009 | C6: P103 | D6: 27/09/2025 | E6: 07/10/2025 | F6: Mohit Verma | G6: Male | H6: 13/04/1976 | I6: Delhi | J6: North | K6: Electronics | L6: Keyboard | M6: 8 | N6: 1200 | O6: 5 | P6: 9120 | Q6: 2 | R6: Card | S6: Aisha | T6: mohit.verma@company.com | U6: 9724635978 | V6: Pending
A7: ORD10006 | B7: C007 | C7: P202 | D7: 04/01/2026 | E7: 12/01/2026 | F7: arjun Rao | G7: Male | H7: 07/02/1988 | I7: Hyderabad | J7: South | K7: Home Appliances | L7: Iron | M7: 4 | N7: 2200 | O7: 0 | P7: 8800 | Q7: 1 | R7: UPI | S7: Ritika | T7: arjun.rao@company.com | U7: 9780584905 | V7: Completed
A8: ORD10007 | B8: C008 | C8: P201 | D8: 31/02/2025 | E8: 25/02/2026 | F8: Kavya Nair | G8: Female | H8: 20/03/2003 | I8: Hyderabad | J8: South | K8: Home Appliances | L8: Mixer | M8: 2 | N8: 3500 | O8: 5 | P8: 6650 | Q8: 1 | R8: UPI | S8: Ritika | T8: kavya.nair@company.com | U8: 9958252176 | V8: Completed
A9: ORD10008 | B9: C002 | C9: P104 | D9: 13/04/2025 | E9: 19/04/2025 | F9: Priya Patel | G9: Female | H9: 07/03/1995 | I9: Mumbai | J9: West | K9: Electronics | L9: Monitor | M9: 14 | N9: 12000 | O9: 15 | P9: 142800 | Q9: 4 | R9: NetBanking | S9: Ritika | T9: priYa.patel@company.com | U9: 9705521654 | V9: Completed
A10: ORD10009 | B10: C008 | C10: P104 | D10: 31/01/2026 | E10: 02/02/2026 | F10: kavya Nair | G10: Female | H10: 06/04/1997 | I10: Pune | J10: West | K10: Electronics | L10: Monitor | M10: 4 | N10: 12000 | O10: 15 | P10: 40800 | Q10: 4 | R10: UPI | S10: Neha | T10: kavya.nair@company.com | U10: 9588041011 | V10: Completed
A11: ORD10010 | B11: C002 | C11: P301 | D11: 25/03/2025 | E11: 27/03/2025 | F11: Priya Patel | G11: Female | H11: 07/01/1990 | I11: Mumbai | J11: West | K11: Stationery | L11: Notebook | M11: 6 | N11: 60 | O11: 0 | P11: 360 | Q11: 4 | R11: Card | S11: Neha | T11: PRiya.patel@company.com | U11: 9340540608 | V11: Completed
A12: ORD10011 | B12: C003 | C12: P202 | D12: 19/09/2025 | E12: 23/09/2025 | F12: Rohit Singh | G12: Male | H12: 10/05/1982 | I12: Delhi | J12: North | K12: Home Appliances | L12: Iron | M12: -3 | N12: 2200 | O12: 0 | P12: 35200 | Q12: 2 | R12: Card | S12: Rahul | T12: rohit.singh@company.com | U12: 9521710321 | V12: Pending
A13: ORD10012 | B13: C008 | C13: P201 | D13: 08/03/2025 | E13: 15/03/2025 | F13: Kavya Nair | G13: Female | H13: 23/01/1982 | I13: Ahmedabad | J13: West | K13: Home Appliances | L13: Mixer | M13: 10 | N13: 3500 | O13: 5 | P13: 33250 | Q13: 5 | R13: Card | S13: Aisha | T13: kavya.nair@company.com | U13: 9123535241 | V13: Cancelled
... A39: ORD10038 | B39: C006 | C39: P201 | D39: 08/03/2026 | E39: 20/03/2026 | F39: Sneha Joshi | G39: Female | H39: 21/06/1980 | I39: Delhi | J39: North | K39: Home Appliances | L39: Mixer | M39: 20 | N39: 3500 | O39: 10 | P39: 63000 | Q39: 3 | R39: Card | S39: Rahul | T39: sneha.joshi@company.com | U39: 9283578533 | V39: Cancelled
A40: ORD10039 | B40: C008 | C40: P302 | D40: 13/02/2025 | E40: 19/02/2025 | F40: Kavya Nair | G40: Female | H40: 17/06/1979 | I40: Pune | J40: West | K40: Stationery | L40: Pen | M40: 5 | N40: 1200 | O40: 0 | P40: 100 | Q40: 1 | R40: Cash | S40: Rahul | T40: kavya.nair@company.com | U40: 9963005771 | V40: Cancelled
A41: ORD10040 | B41: C010 | C41: P203 | D41: 05/10/2025 | E41: 15/10/2025 | F41: Pooja Shah | G41: Female | H41: 18/06/1992 | I41: Mumbai | J41: West | K41: Home Appliances | L41: Microwave | M41: 20 | N41: 8500 | O41: 0 | P41: 170000 | Q41: 1 | R41: UPI | S41: Neha | T41: pooja.shah@company.com | U41: 9484632635 | V41: Cancelled
A42: ORD10041 | B42: C007 | C42: P301 | D42: 10/02/2026 | E42: 12/02/2026 | F42: Arjun Rao | G42: Male | H42: 06/06/1994 | I42: Bengaluru | J42: South | K42: Stationery | L42: Notebook | M42: 8 | N42: 60 | O42: 15 | P42: 408 | Q42: 5 | R42: UPI | S42: Rahul | T42: arjun.rao@company.com | U42: 9276319484 | V42: Pending
A43: ORD10042 | B43: C010 | C43: P201 | D43: 04/06/2025 | E43: 16/06/2025 | F43: Pooja Shah | G43: Female | H43: 22/09/1988 | I43: Pune | J43: West | K43: Home Appliances | L43: Mixer | M43: 8 | N43: 3500 | O43: 5 | P43: 26600 | Q43: 1 | R43: Card | S43: Neha | T43: pooja.shah@company.com | U43: 9619034852 | V43: Pending
A44: ORD10043 | B44: C009 | C44: P203 | D44: 08/02/2026 | E44: 14/02/2026 | F44: Mohit Verma | G44: Male | H44: 14/07/2001 | I44: Jaipur | J44: North | K44: Home Appliances | L44: Microwave | M44: 1 | N44: 8500 | O44: 0 | P44: 8500 | Q44: 2 | R44: Card | S44: Neha | T44: mohit.verma@company.com | U44: 9636416962 | V44: Pending
A45: ORD10044 | B45: C001 | C45: P303 | D45: 30/03/2025 | E45: 31/03/2025 | F45: amit Sharma | G45: Male | H45: 09/08/1991 | I45: Pune | J45: West | K45: Stationery | L45: Marker | M45: 8 | N45: 45 | O45: 15 | P45: 306 | Q45: 2 | R45: Card | S45: Aisha | T45: amit.sharma@company.com | U45: 9357133880 | V45: Completed
A46: ORD10045 | B46: C006 | C46: P202 | D46: 25/04/2025 | E46: 28/04/2025 | F46: Sneha Joshi | G46: Female | H46: 21/10/1988 | I46: Pune | J46: West | K46: Home Appliances | L46: Iron | M46: 16 | N46: 2200 | O46: 5 | P46: 33440 | Q46: 5 | R46: Card | S46: Aisha | T46: sneha.joshi@company.com | U46: 9575210324 | V46: Cancelled
A47: ORD10046 | B47: C009 | C47: P201 | D47: 13/10/2025 | E47: 23/10/2025 | F47: Mohit Verma | G47: Male | H47: 19/11/2002 | I47: Bengaluru | J47: South | K47: Home Appliances | L47: Mixer | M47: 19 | N47: 3500 | O47: 20 | P47: 53200 | Q47: 3 | R47: Cash | S47: Karan | T47: mohit.verma@company.com | U47: 9276080204 | V47: Cancelled
A48: ORD10047 | B48: C006 | C48: P102 | D48: 11/10/2025 | E48: 14/10/2025 | F48: Sneha Joshi | G48: Female | H48: 06/07/2000 | I48: Pune | J48: West | K48: Electronics | L48: Mouse | M48: 15 | N48: 700 | O48: 15 | P48: 8925 | Q48: 4 | R48: UPI | S48: Neha | T48: sneha.joshicompany.com | U48: 9856624471 | V48: Completed
A49: ORD10048 | B49: C006 | C49: P102 | D49: 27/11/2025 | E49: 03/12/2025 | F49: Sneha Joshi | G49: Female | H49: 26/11/1998 | I49: Jaipur | J49: North | K49: Electronics | L49: Mouse | M49: 19 | N49: 700 | O49: 20 | P49: 10640 | Q49: 1 | R49: Cash | S49: Neha | T49: sneha.joshi@company.com | U49: 9238141322 | V49: Completed
A50: ORD10049 | B50: C009 | C50: P104 | D50: 19/04/2026 | F50: Mohit Verma | G50: Male | H50: 03/06/1996 | I50: Delhi | J50: North | K50: Electronics | L50: Monitor | M50: 19 | N50: 12000 | O50: 0 | P50: 228000 | Q50: 1 | R50: NetBanking | S50: Aisha | T50: mohit.verma@company.com | U50: 9890380030 | V50: Completed
A51: ORD10050 | B51: C004 | C51: P103 | D51: 19/04/2026 | E51: 21/04/2026 | F51: Anita Gupta | G51: Female | H51: 15/03/1987 | I51: Pune | J51: West | K51: Electronics | L51: Keyboard | M51: 6 | N51: 1200 | O51: 5 | P51: 6840 | Q51: 2 | R51: Cash | S51: Ritika | T51: anita.gupta@company.com | U51: 9495893170 | V51: Pending
A52: ORD10051 | B52: C010 | C52: P202 | D52: 28/03/2025 | E52: 07/04/2025 | F52: POoja Shah | G52: Female | H52: 20/02/1979 | I52: Bengaluru | J52: South | K52: Home Appliances | L52: Iron | M52: 7 | N52: 2200 | O52: 15 | P52: 13090 | Q52: 1 | R52: UPI | S52: Aisha | T52: pooja.shah@company.com | U52: 9485166307 | V52: Completed
A53: ORD10052 | B53: C002 | C53: P301 | D53: 25/08/2025 | E53: 28/08/2025 | F53: Priya Patel | G53: Female | H53: 09/08/2000 | I53: Jaipur | J53: North | K53: Stationery | L53: Notebook | M53: 8 | N53: 60 | O53: 10 | P53: 432 | Q53: 5 | R53: Card | S53: Aisha | T53: priya.patel@company.com | U53: 9924709648 | V53: Cancelled
A54: ORD10053 | B54: C005 | C54: P101 | D54: 19/08/2025 | E54: 23/08/2025 | F54: Vikas Mehta | G54: Male | H54: 17/01/1976 | I54: Kolkata | J54: East | K54: Electronics | L54: Laptop | M54: 12 | N54: 55000 | O54: 5 | P54: 627000 | Q54: 2 | R54: UPI | S54: Rahul | T54: vikas.mehta@company.com | U54: 9350554626 | V54: Pending
A55: ORD10054 | B55: C008 | C55: P102 | D55: 27/07/2025 | E55: 05/08/2025 | F55: Kavya Nair | G55: Female | H55: 04/04/1975 | I55: Jaipur | J55: North | K55: Electronics | L55: Mouse | M55: 3 | N55: 700 | O55: 0 | P55: 2100 | Q55: 3 | R55: Card | S55: Karan | T55: kavya.nair@company.com | U55: 9743295580 | V55: Cancelled
A56: ORD10055 | B56: C003 | C56: P301 | D56: 21/02/2025 | E56: 26/02/2025 | F56: RoHit Singh | G56: Male | H56: 11/12/1976 | I56: Ahmedabad | J56: West | K56: Stationery | L56: Notebook | M56: 19 | N56: 60 | O56: 15 | P56: 969 | Q56: 4 | R56: Card | S56: Rahul | T56: rohit.singh@company.com | U56: 9822926495 | V56: Cancelled
A57: ORD10056 | B57: C001 | C57: P301 | D57: 10/08/2025 | E57: 11/08/2025 | F57: Amit Sharma | G57: Male | H57: 03/12/1979 | I57: Jaipur | J57: North | K57: Stationery | L57: Notebook | M57: 9 | N57: 60 | O57: 20 | P57: 432 | Q57: 1 | R57: NetBanking | S57: Neha | T57: amit.sharma@company.com | U57: 9518298190 | V57: Pending
A58: ORD10057 | B58: C001 | C58: P102 | D58: 24/03/2026 | E58: 30/03/2026 | F58: Amit Sharma | G58: Male | H58: 27/12/1978 | I58: Bengaluru | J58: South | K58: Electronics | L58: Mouse | M58: 6 | N58: 700 | O58: 0 | P58: 4200 | Q58: 4 | R58: UPI | S58: Rahul | T58: amit.sharmcompany.com | U58: 9366223547 | V58: Cancelled
A59: ORD10058 | B59: C003 | C59: P303 | D59: 13/03/2026 | E59: 19/03/2026 | F59: Rohit Singh | G59: Male | H59: 15/04/1975 | I59: Delhi | J59: North | K59: Stationery | L59: Marker | M59: 18 | N59: 45 | O59: 5 | P59: 769.5 | Q59: 1 | R59: Card | S59: Aisha | T59: rohit.singh@company.com | U59: 9701988524 | V59: Pending
A60: ORD10059 | B60: C007 | C60: P302 | D60: 15/06/2025 | E60: 26/06/2025 | F60: Arjun Rao | G60: Male | H60: 19/12/1988 | I60: Jaipur | J60: North | K60: Stationery | L60: Pen | M60: 8 | N60: 20 | O60: 5 | P60: 152 | Q60: 1 | R60: Card | S60: Ritika | T60: arjun.rao@company.com | U60: 9836327649 | V60: completed
A61: ORD10060 | B61: C005 | C61: P102 | D61: 05/03/2025 | E61: 06/03/2025 | F61: Vikas Mehta | G61: Male | H61: 07/03/1979 | I61: Jaipur | J61: North | K61: Electronics | L61: Mouse | M61: 8 | N61: 700 | O61: 10 | P61: 5040 | Q61: 1 | R61: NetBanking | S61: Aisha | T61: Vikas.mehta@company.com | U61: 9261800516 | V61: Cancelled
A62: ORD10061 | B62: C008 | C62: P302 | D62: 09/04/2026 | E62: 19/04/2026 | F62: Kavya Nair | G62: Female | H62: 17/12/2003 | I62: Delhi | J62: North | K62: Stationery | L62: Pen | M62: 7 | N62: 20 | O62: 15 | P62: 119 | Q62: 5 | R62: Card | S62: Rahul | T62: kavya.nair@company.com | U62: 9950802015 | V62: Completed
... A74: ORD10073 | B74: C008 | C74: P103 | D74: 13/12/2025 | E74: 23/12/2025 | F74: Kavya Nair | G74: Female | H74: 22/09/1981 | I74: Jaipur | J74: North | K74: Electronics | L74: Keyboard | M74: 1 | N74: 1200 | O74: 5 | P74: 1140 | Q74: 3 | R74: UPI | S74: Aisha | T74: kavya.nair@company.com | U74: 9808988530 | V74: Cancelled
A75: ORD10074 | B75: C010 | C75: P202 | D75: 04/02/2026 | E75: 16/02/2026 | F75: Pooja Shah | G75: Female | H75: 20/06/1980 | J75: South | K75: Home Appliances | L75: Iron | M75: 1 | N75: 2200 | O75: 15 | P75: 1870 | Q75: 4 | R75: Card | S75: Aisha | T75: pooja.shah@company.com | U75: 9286410494 | V75: Completed
A76: ORD10075 | B76: C003 | C76: P103 | D76: 26/01/2026 | E76: 28/01/2026 | F76: Rohit Singh | G76: Male | H76: 02/11/1982 | I76: Pune | J76: West | K76: Electronics | L76: Keyboard | M76: 3 | N76: 1200 | O76: 10 | P76: 3240 | Q76: 5 | R76: Cash | S76: Rahul | T76: rohit.singh@company.com | U76: 9311555196 | V76: Completed
...

Sheet Product_Master
A1: Product_ID | B1: Product_Name | C1: Category | D1: Supplier | E1: Cost_Price | F1: Warranty_Months
A2: P101 | B2: Laptop | C2: Electronics | D2: TechHub | E2: 41250 | F2: 12
A3: P102 | B3: Mouse | C3: Electronics | D3: TechHub | E3: 525 | F3: 24
A4: P103 | B4: Keyboard | C4: Electronics | D4: TechHub | E4: 900 | F4: 6
A5: P104 | B5: Monitor | C5: Electronics | D5: Global Trade | E5: 9000 | F5: 24
A6: P201 | B6: Mixer | C6: Home Appliances | D6: Global Trade | E6: 2625 | F6: 6
A7: P202 | B7: Iron | C7: Home Appliances | D7: Global Trade | E7: 1650 | F7: 24
A8: P203 | B8: Microwave | C8: Home Appliances | D8: TechHub | E8: 6375 | F8: 24
A9: P301 | B9: Notebook | C9: Stationery | D9: ABC Corp | E9: 45 | F9: 12
A10: P302 | B10: Pen | C10: Stationery | D10: Prime Supplies | E10: 15 | F10: 12
A11: P303 | B11: Marker | C11: Stationery | D11: TechHub | E11: 33.75 | F11: 12

Sheet Custumer_Master
A1: Customer_ID | B1: Customer_Name | C1: Membership | D1: State | F1: Gender | G1: DOB | H1: Email | I1: City | J1: Region | K1: Birthday Month
A2: C001 | B2: Amit Sharma | C2: Silver | D2: RJ | F2: =VLOOKUP($A2,Sales_data!$B:$V,6,FALSE) -> Male | G2: =VLOOKUP($A2,Sales_data!$B:$V,7,FALSE) -> 09/08/1991 | H2: =VLOOKUP($A2,Sales_data!$B:$V,19,FALSE) -> amit.sharma@company.com | I2: =VLOOKUP($A2,Sales_data!$B:$V,8,FALSE) -> Pune | J2: =VLOOKUP($A2,Sales_data!$B:$V,9,FALSE) -> West | K2: =TEXT(IFERROR(DATEVALUE(G2), G2), "mmmm") -> August
A3: C002 | B3: Priya Patel | C3: Platinum | D3: WB | F3: =VLOOKUP($A3,Sales_data!$B:$V,6,FALSE) -> Female | G3: =VLOOKUP($A3,Sales_data!$B:$V,7,FALSE) -> 07/03/1995 | H3: =VLOOKUP($A3,Sales_data!$B:$V,19,FALSE) -> priYa.patel@company.com | I3: =VLOOKUP($A3,Sales_data!$B:$V,8,FALSE) -> Mumbai | J3: =VLOOKUP($A3,Sales_data!$B:$V,9,FALSE) -> West | K3: =TEXT(IFERROR(DATEVALUE(G3), G3), "mmmm") -> March
A4: C003 | B4: Rohit Singh | C4: Gold | D4: DL | F4: =VLOOKUP($A4,Sales_data!$B:$V,6,FALSE) -> Male | G4: =VLOOKUP($A4,Sales_data!$B:$V,7,FALSE) -> 10/05/1982 | H4: =VLOOKUP($A4,Sales_data!$B:$V,19,FALSE) -> rohit.singh@company.com | I4: =VLOOKUP($A4,Sales_data!$B:$V,8,FALSE) -> Delhi | J4: =VLOOKUP($A4,Sales_data!$B:$V,9,FALSE) -> North | K4: =TEXT(IFERROR(DATEVALUE(G4), G4), "mmmm") -> May
A5: C004 | B5: Anita Gupta | C5: Gold | D5: WB | F5: =VLOOKUP($A5,Sales_data!$B:$V,6,FALSE) -> Female | G5: =VLOOKUP($A5,Sales_data!$B:$V,7,FALSE) -> 16/01/2002 | H5: =VLOOKUP($A5,Sales_data!$B:$V,19,FALSE) -> anita.gupta@company.com | I5: =VLOOKUP($A5,Sales_data!$B:$V,8,FALSE) -> Pune | J5: =VLOOKUP($A5,Sales_data!$B:$V,9,FALSE) -> West | K5: =TEXT(IFERROR(DATEVALUE(G5), G5), "mmmm") -> January
A6: C005 | B6: Vikas Mehta | C6: Gold | D6: DL | F6: =VLOOKUP($A6,Sales_data!$B:$V,6,FALSE) -> Male | G6: =VLOOKUP($A6,Sales_data!$B:$V,7,FALSE) -> 03/08/1991 | H6: =VLOOKUP($A6,Sales_data!$B:$V,19,FALSE) -> vikas.mehta@company.com | I6: =VLOOKUP($A6,Sales_data!$B:$V,8,FALSE) -> Mumbai | J6: =VLOOKUP($A6,Sales_data!$B:$V,9,FALSE) -> West | K6: =TEXT(IFERROR(DATEVALUE(G6), G6), "mmmm") -> August
A7: C006 | B7: Sneha Joshi | C7: Gold | D7: WB | F7: =VLOOKUP($A7,Sales_data!$B:$V,6,FALSE) -> Female | G7: =VLOOKUP($A7,Sales_data!$B:$V,7,FALSE) -> 04/04/1981 | H7: =VLOOKUP($A7,Sales_data!$B:$V,19,FALSE) -> sneha.joshi@company.com | I7: =VLOOKUP($A7,Sales_data!$B:$V,8,FALSE) -> Pune | J7: =VLOOKUP($A7,Sales_data!$B:$V,9,FALSE) -> West | K7: =TEXT(IFERROR(DATEVALUE(G7), G7), "mmmm") -> April
A8: C007 | B8: Arjun Rao | C8: Silver | D8: RJ | F8: =VLOOKUP($A8,Sales_data!$B:$V,6,FALSE) -> Male | G8: =VLOOKUP($A8,Sales_data!$B:$V,7,FALSE) -> 07/02/1988 | H8: =VLOOKUP($A8,Sales_data!$B:$V,19,FALSE) -> arjun.rao@company.com | I8: =VLOOKUP($A8,Sales_data!$B:$V,8,FALSE) -> Hyderabad | J8: =VLOOKUP($A8,Sales_data!$B:$V,9,FALSE) -> South | K8: =TEXT(IFERROR(DATEVALUE(G8), G8), "mmmm") -> February
A9: C008 | B9: Kavya Nair | C9: Silver | D9: WB | F9: =VLOOKUP($A9,Sales_data!$B:$V,6,FALSE) -> Female | G9: =VLOOKUP($A9,Sales_data!$B:$V,7,FALSE) -> 01/08/1976 | H9: =VLOOKUP($A9,Sales_data!$B:$V,19,FALSE) -> KAvya.nair@company.com | I9: =VLOOKUP($A9,Sales_data!$B:$V,8,FALSE) -> Hyderabad | J9: =VLOOKUP($A9,Sales_data!$B:$V,9,FALSE) -> South | K9: =TEXT(IFERROR(DATEVALUE(G9), G9), "mmmm") -> August
A10: C009 | B10: Mohit Verma | C10: Platinum | D10: KA | F10: =VLOOKUP($A10,Sales_data!$B:$V,6,FALSE) -> Male | G10: =VLOOKUP($A10,Sales_data!$B:$V,7,FALSE) -> 13/04/1976 | H10: =VLOOKUP($A10,Sales_data!$B:$V,19,FALSE) -> mohit.verma@company.com | I10: =VLOOKUP($A10,Sales_data!$B:$V,8,FALSE) -> Delhi | J10: =VLOOKUP($A10,Sales_data!$B:$V,9,FALSE) -> North | K10: =TEXT(IFERROR(DATEVALUE(G10), G10), "mmmm") -> April
A11: C010 | B11: Pooja Shah | C11: Silver | D11: WB | F11: =VLOOKUP($A11,Sales_data!$B:$V,6,FALSE) -> Female | G11: =VLOOKUP($A11,Sales_data!$B:$V,7,FALSE) -> 16/09/1994 | H11: =VLOOKUP($A11,Sales_data!$B:$V,19,FALSE) -> pooja.shah@company.com | I11: =VLOOKUP($A11,Sales_data!$B:$V,8,FALSE) -> Bengaluru | J11: =VLOOKUP($A11,Sales_data!$B:$V,9,FALSE) -> South | K11: =TEXT(IFERROR(DATEVALUE(G11), G11), "mmmm") -> September

Sheet Data Cleaning
A1: CLEAN AND MODIFY RAW DATA TO INFORMATION - Pre Requiste Work on - "Complie Data"
A21: Table 1 | C21: Table 2 | E21: Table 3 | G21: Apllied Cleaning And Modification
G22: Changes Done on Coloumn | H22: Changes Done | I22: Result | J22: Format
A23: Sales_Data | C23: Product_Master | E23: Custumer_Master | G23: Order_ID | H23: Replacing second Repated Order ID ORD10002 with ORD10004 & Replacing second Repated Order ID ORD10020 with ORD10049 | I23: 2 Values are not Unique - (ORD10002 & ORD10020) | J23: Genral
G24: Customer_ID | H24: - | I24: All values are in foramt | J24: Genral
G25: Product_ID | H25: - | I25: All values are in foramt | J25: Genral
G26: Order_Date | H26: Foramt Change - Missing Dates | I26: Format Changed from genral to Date | J26: Date
G27: Delivery_Date | H27: Foramt Change - Missing Dates | I27: Format Changed from genral to Date | J27: Date
G28: Customer_Name | H28: Trim and Proper | I28: Alligning all the data and removing extra spaces | J28: Genral
G29: Gender | H29: Trim and Proper | I29: Alligning all the data and removing extra spaces | J29: Genral
G30: DOB | H30: Foramt Change - Missing Dates - Mapped with help of Custumer ID | I30: Format Changed from genral to Date | J30: Date
G31: City | H31: Trim and Proper - Missing Values - Remapped with Custumer Master | I31: Alligning all the data and removing extra spaces | J31: Genral
G32: Region | H32: Trim and Proper - Missing Values - Remapped with Custumer Master | I32: Alligning all the data and removing extra spaces | J32: Genral
G33: Category | H33: Trim and Proper - Re mapped as per Product Master | I33: Alligning all the data and removing extra spaces and Spelling Mistakes | J33: Genral
G34: Product_Name | H34: Trim and Proper - Re mapped as per Product Master | I34: Alligning all the data and removing extra spaces | J34: Genral
G35: Quantity | H35: Data Validation - and fourmula used to remove negative and text numbers | I35: All numbers in between 1 to 50 | J35: Number
... G43: Phone | H43: Used if statement with trim but still 1 number is invalid | I43: Foramt Change | J43: Number

Sheet Final Data
A1: Order_ID | B1: Customer_ID | C1: Product_ID | D1: Order_Date | E1: Delivery_Date | F1: Customer_Name | G1: Gender | H1: DOB | I1: City | J1: Region | K1: State | L1: Category | M1: Product_Name_Final | N1: Quantity | O1: Unit_Price | P1: Discount_% | Q1: New Sales Calculation | R1: Rating | S1: Payment_Mode | T1: Salesperson | U1: Email | V1: Phone | W1: Supplier | X1: Warranty_Months | Y1: Membership | Z1: Warranty_Till(Months) | AA1: Birthday Month | AB1: Custumer Classification | AC1: Custumer Code | AD1: Customer Age | AE1: Delivery Time (Days) | AF1: Delivery Status | AG1: Order Status
A2: ORD10001 | B2: C008 | C2: P202 | D2: 45918 | E2: 22/09/2025 | F2: =VLOOKUP(B2,Custumer_Master!A:D,2,FALSE) -> Kavya Nair | G2: =VLOOKUP($B2,Custumer_Master!$A:$J,6,FALSE) -> Female | H2: =VLOOKUP($B2,Custumer_Master!$A:$J,7,FALSE) -> 01/08/1976 | I2: =VLOOKUP($B2,Custumer_Master!$A:$J,9,FALSE) -> Hyderabad | J2: =VLOOKUP($B2,Custumer_Master!$A:$J,10,FALSE) -> South | K2: =VLOOKUP(B2,Custumer_Master!A:D,4,FALSE) -> WB | L2: =PROPER(TRIM(VLOOKUP('Final Data'!C2,Product_Master!A:F,3,FALSE))) -> Home Appliances | M2: Iron | N2: 4 | O2: =VLOOKUP(C2,Product_Master!A:F,5,FALSE) -> 1650 | P2: 0.1 | Q2: =(N2*O2)-(N2*O2)*P2 -> 5940 | R2: 4 | S2: Cash | T2: Ritika | U2: kavya.nair@company.com | V2: 9431429797 | W2: =VLOOKUP(C2,Product_Master!A:F,4,FALSE) -> Global Trade | X2: =VLOOKUP(C2,Product_Master!A:F,6,FALSE) -> 24 | Y2: =VLOOKUP(B2,Custumer_Master!A:D,3,FALSE) -> Silver | Z2: =EDATE(E2,X2) -> 46652 | AA2: =VLOOKUP(B2,Custumer_Master!A:K,11,) -> August | AB2: Silver | AC2: =PROPER(LEFT(TRIM(F2), 3)) & RIGHT(TRIM(B2), 3) & PROPER(LEFT(TRIM(I2), 2)) -> Kav008Hy | AD2: =DATEDIF(H2, TODAY(), "Y") -> 49 | AE2: =IFERROR(IF(OR(E2="", D2="", LOWER(TRIM(E2))="pending", LOWER(TRIM(D2))="pending"), "Pending", E2 - D2), "Pending") -> 4 | AF2: =IFERROR(IF(OR(E2="", D2="","Pending","Pending"), "Pending", IF((E2 - D2) <= 5, "On Time", "Delayed")), "Pending") -> On Time | AG2: =IF(AF2="Pending","Pending","Completed") -> Completed
A3: ORD10002 | B3: C008 | C3: P104 | D3: 45774 | E3: 04/05/2025 | F3: =VLOOKUP(B3,Custumer_Master!A:D,2,FALSE) -> Kavya Nair | G3: =VLOOKUP($B3,Custumer_Master!$A:$J,6,FALSE) -> Female | H3: =VLOOKUP($B3,Custumer_Master!$A:$J,7,FALSE) -> 01/08/1976 | I3: =VLOOKUP($B3,Custumer_Master!$A:$J,9,FALSE) -> Hyderabad | J3: =VLOOKUP($B3,Custumer_Master!$A:$J,10,FALSE) -> South | K3: =VLOOKUP(B3,Custumer_Master!A:D,4,FALSE) -> WB | L3: =PROPER(TRIM(VLOOKUP('Final Data'!C3,Product_Master!A:F,3,FALSE))) -> Electronics | M3: Monitor | N3: 17 | O3: =VLOOKUP(C3,Product_Master!A:F,5,FALSE) -> 9000 | P3: 0.1 | Q3: =(N3*O3)-(N3*O3)*P3 -> 137700 | R3: 1 | S3: Netbanking | T3: Rahul | U3: kavya.nair@company.com | V3: 9129865339 | W3: =VLOOKUP(C3,Product_Master!A:F,4,FALSE) -> Global Trade | X3: =VLOOKUP(C3,Product_Master!A:F,6,FALSE) -> 24 | Y3: =VLOOKUP(B3,Custumer_Master!A:D,3,FALSE) -> Silver | Z3: =EDATE(E3,X3) -> 46511 | AA3: =VLOOKUP(B3,Custumer_Master!A:K,11,) -> August | AB3: Blacklisted | AC3: =PROPER(LEFT(TRIM(F3), 3)) & RIGHT(TRIM(B3), 3) & PROPER(LEFT(TRIM(I3), 2)) -> Kav008Hy | AD3: =DATEDIF(H3, TODAY(), "Y") -> 49 | AE3: =IFERROR(IF(OR(E3="", D3="", LOWER(TRIM(E3))="pending", LOWER(TRIM(D3))="pending"), "Pending", E3 - D3), "Pending") -> 7 | AF3: =IFERROR(IF(OR(E3="", D3="","Pending","Pending"), "Pending", IF((E3 - D3) <= 5, "On Time", "Delayed")), "Pending") -> Delayed | AG3: =IF(AF3="Pending","Pending","Completed") -> Completed
A4: ORD10003 | B4: C010 | C4: P101 | D4: 45903 | E4: 14/09/2025 | F4: =VLOOKUP(B4,Custumer_Master!A:D,2,FALSE) -> Pooja Shah | G4: =VLOOKUP($B4,Custumer_Master!$A:$J,6,FALSE) -> Female | H4: =VLOOKUP($B4,Custumer_Master!$A:$J,7,FALSE) -> 16/09/1994 | I4: =VLOOKUP($B4,Custumer_Master!$A:$J,9,FALSE) -> Bengaluru | J4: =VLOOKUP($B4,Custumer_Master!$A:$J,10,FALSE) -> South | K4: =VLOOKUP(B4,Custumer_Master!A:D,4,FALSE) -> WB | L4: =PROPER(TRIM(VLOOKUP('Final Data'!C4,Product_Master!A:F,3,FALSE))) -> Electronics | M4: Laptop | N4: 5 | O4: =VLOOKUP(C4,Product_Master!A:F,5,FALSE) -> 41250 | P4: 0.05 | Q4: =(N4*O4)-(N4*O4)*P4 -> 195937.5 | R4: 3 | S4: Netbanking | T4: Aisha | U4: pooja.shah@company.com | V4: 9380975626 | W4: =VLOOKUP(C4,Product_Master!A:F,4,FALSE) -> TechHub | X4: =VLOOKUP(C4,Product_Master!A:F,6,FALSE) -> 12 | Y4: =VLOOKUP(B4,Custumer_Master!A:D,3,FALSE) -> Silver | Z4: =EDATE(E4,X4) -> 46279 | AA4: =VLOOKUP(B4,Custumer_Master!A:K,11,) -> September | AB4: Gold | AC4: =PROPER(LEFT(TRIM(F4), 3)) & RIGHT(TRIM(B4), 3) & PROPER(LEFT(TRIM(I4), 2)) -> Poo010Be | AD4: =DATEDIF(H4, TODAY(), "Y") -> 31 | AE4: =IFERROR(IF(OR(E4="", D4="", LOWER(TRIM(E4))="pending", LOWER(TRIM(D4))="pending"), "Pending", E4 - D4), "Pending") -> 11 | AF4: =IFERROR(IF(OR(E4="", D4="","Pending","Pending"), "Pending", IF((E4 - D4) <= 5, "On Time", "Delayed")), "Pending") -> Delayed | AG4: =IF(AF4="Pending","Pending","Completed") -> Completed
A5: ORD10004 | B5: C008 | C5: P202 | D5: 46102 | E5: 02/04/2026 | F5: =VLOOKUP(B5,Custumer_Master!A:D,2,FALSE) -> Kavya Nair | G5: =VLOOKUP($B5,Custumer_Master!$A:$J,6,FALSE) -> Female | H5: =VLOOKUP($B5,Custumer_Master!$A:$J,7,FALSE) -> 01/08/1976 | I5: =VLOOKUP($B5,Custumer_Master!$A:$J,9,FALSE) -> Hyderabad | J5: =VLOOKUP($B5,Custumer_Master!$A:$J,10,FALSE) -> South | K5: =VLOOKUP(B5,Custumer_Master!A:D,4,FALSE) -> WB | L5: =PROPER(TRIM(VLOOKUP('Final Data'!C5,Product_Master!A:F,3,FALSE))) -> Home Appliances | M5: Iron | N5: 5 | O5: =VLOOKUP(C5,Product_Master!A:F,5,FALSE) -> 1650 | P5: 0.05 | Q5: =(N5*O5)-(N5*O5)*P5 -> 7837.5 | R5: 5 | S5: Netbanking | T5: Aisha | U5: kavya.nair@company.com | V5: 9600261125 | W5: =VLOOKUP(C5,Product_Master!A:F,4,FALSE) -> Global Trade | X5: =VLOOKUP(C5,Product_Master!A:F,6,FALSE) -> 24 | Y5: =VLOOKUP(B5,Custumer_Master!A:D,3,FALSE) -> Silver | Z5: =EDATE(E5,X5) -> 46845 | AA5: =VLOOKUP(B5,Custumer_Master!A:K,11,) -> August | AB5: Silver | AC5: =PROPER(LEFT(TRIM(F5), 3)) & RIGHT(TRIM(B5), 3) & PROPER(LEFT(TRIM(I5), 2)) -> Kav008Hy | AD5: =DATEDIF(H5, TODAY(), "Y") -> 49 | AE5: =IFERROR(IF(OR(E5="", D5="", LOWER(TRIM(E5))="pending", LOWER(TRIM(D5))="pending"), "Pending", E5 - D5), "Pending") -> 12 | AF5: =IFERROR(IF(OR(E5="", D5="","Pending","Pending"), "Pending", IF((E5 - D5) <= 5, "On Time", "Delayed")), "Pending") -> Delayed | AG5: =IF(AF5="Pending","Pending","Completed") -> Completed
A6: ORD10005 | B6: C009 | C6: P103 | D6: 45927 | E6: 07/10/2025 | F6: =VLOOKUP(B6,Custumer_Master!A:D,2,FALSE) -> Mohit Verma | G6: =VLOOKUP($B6,Custumer_Master!$A:$J,6,FALSE) -> Male | H6: =VLOOKUP($B6,Custumer_Master!$A:$J,7,FALSE) -> 13/04/1976 | I6: =VLOOKUP($B6,Custumer_Master!$A:$J,9,FALSE) -> Delhi | J6: =VLOOKUP($B6,Custumer_Master!$A:$J,10,FALSE) -> North | K6: =VLOOKUP(B6,Custumer_Master!A:D,4,FALSE) -> KA | L6: =PROPER(TRIM(VLOOKUP('Final Data'!C6,Product_Master!A:F,3,FALSE))) -> Electronics | M6: Keyboard | N6: 8 | O6: =VLOOKUP(C6,Product_Master!A:F,5,FALSE) -> 900 | P6: 0.05 | Q6: =(N6*O6)-(N6*O6)*P6 -> 6840 | R6: 2 | S6: Card | T6: Aisha | U6: mohit.verma@company.com | V6: 9724635978 | W6: =VLOOKUP(C6,Product_Master!A:F,4,FALSE) -> TechHub | X6: =VLOOKUP(C6,Product_Master!A:F,6,FALSE) -> 6 | Y6: =VLOOKUP(B6,Custumer_Master!A:D,3,FALSE) -> Platinum | Z6: =EDATE(E6,X6) -> 46119 | AA6: =VLOOKUP(B6,Custumer_Master!A:K,11,) -> April | AB6: Blacklisted | AC6: =PROPER(LEFT(TRIM(F6), 3)) & RIGHT(TRIM(B6), 3) & PROPER(LEFT(TRIM(I6), 2)) -> Moh009De | AD6: =DATEDIF(H6, TODAY(), "Y") -> 50 | AE6: =IFERROR(IF(OR(E6="", D6="", LOWER(TRIM(E6))="pending", LOWER(TRIM(D6))="pending"), "Pending", E6 - D6), "Pending") -> 10 | AF6: =IFERROR(IF(OR(E6="", D6="","Pending","Pending"), "Pending", IF((E6 - D6) <= 5, "On Time", "Delayed")), "Pending") -> Delayed | AG6: =IF(AF6="Pending","Pending","Completed") -> Completed
A7: ORD10006 | B7: C007 | C7: P202 | D7: 46026 | E7: 12/01/2026 | F7: =VLOOKUP(B7,Custumer_Master!A:D,2,FALSE) -> Arjun Rao | G7: =VLOOKUP($B7,Custumer_Master!$A:$J,6,FALSE) -> Male | H7: =VLOOKUP($B7,Custumer_Master!$A:$J,7,FALSE) -> 07/02/1988 | I7: =VLOOKUP($B7,Custumer_Master!$A:$J,9,FALSE) -> Hyderabad | J7: =VLOOKUP($B7,Custumer_Master!$A:$J,10,FALSE) -> South | K7: =VLOOKUP(B7,Custumer_Master!A:D,4,FALSE) -> RJ | L7: =PROPER(TRIM(VLOOKUP('Final Data'!C7,Product_Master!A:F,3,FALSE))) -> Home Appliances | M7: Iron | N7: 4 | O7: =VLOOKUP(C7,Product_Master!A:F,5,FALSE) -> 1650 | P7: 0 | Q7: =(N7*O7)-(N7*O7)*P7 -> 6600 | R7: 1 | S7: Upi | T7: Ritika | U7: arjun.rao@company.com | V7: 9780584905 | W7: =VLOOKUP(C7,Product_Master!A:F,4,FALSE) -> Global Trade | X7: =VLOOKUP(C7,Product_Master!A:F,6,FALSE) -> 24 | Y7: =VLOOKUP(B7,Custumer_Master!A:D,3,FALSE) -> Silver | Z7: =EDATE(E7,X7) -> 46764 | AA7: =VLOOKUP(B7,Custumer_Master!A:K,11,) -> February | AB7: Blacklisted | AC7: =PROPER(LEFT(TRIM(F7), 3)) & RIGHT(TRIM(B7), 3) & PROPER(LEFT(TRIM(I7), 2)) -> Arj007Hy | AD7: =DATEDIF(H7, TODAY(), "Y") -> 38 | AE7: =IFERROR(IF(OR(E7="", D7="", LOWER(TRIM(E7))="pending", LOWER(TRIM(D7))="pending"), "Pending", E7 - D7), "Pending") -> 8 | AF7: =IFERROR(IF(OR(E7="", D7="","Pending","Pending"), "Pending", IF((E7 - D7) <= 5, "On Time", "Delayed")), "Pending") -> Delayed | AG7: =IF(AF7="Pending","Pending","Completed") -> Completed
A8: ORD10007 | B8: C008 | C8: P201 | D8: 31/02/2025 | E8: 25/02/2026 | F8: =VLOOKUP(B8,Custumer_Master!A:D,2,FALSE) -> Kavya Nair | G8: =VLOOKUP($B8,Custumer_Master!$A:$J,6,FALSE) -> Female | H8: =VLOOKUP($B8,Custumer_Master!$A:$J,7,FALSE) -> 01/08/1976 | I8: =VLOOKUP($B8,Custumer_Master!$A:$J,9,FALSE) -> Hyderabad | J8: =VLOOKUP($B8,Custumer_Master!$A:$J,10,FALSE) -> South | K8: =VLOOKUP(B8,Custumer_Master!A:D,4,FALSE) -> WB | L8: =PROPER(TRIM(VLOOKUP('Final Data'!C8,Product_Master!A:F,3,FALSE))) -> Home Appliances | M8: Mixer | N8: 2 | O8: =VLOOKUP(C8,Product_Master!A:F,5,FALSE) -> 2625 | P8: 0.05 | Q8: =(N8*O8)-(N8*O8)*P8 -> 4987.5 | R8: 1 | S8: Upi | T8: Ritika | U8: kavya.nair@company.com | V8: 9958252176 | W8: =VLOOKUP(C8,Product_Master!A:F,4,FALSE) -> Global Trade | X8: =VLOOKUP(C8,Product_Master!A:F,6,FALSE) -> 6 | Y8: =VLOOKUP(B8,Custumer_Master!A:D,3,FALSE) -> Silver | Z8: =EDATE(E8,X8) -> 46259 | AA8: =VLOOKUP(B8,Custumer_Master!A:K,11,) -> August | AB8: Blacklisted | AC8: =PROPER(LEFT(TRIM(F8), 3)) & RIGHT(TRIM(B8), 3) & PROPER(LEFT(TRIM(I8), 2)) -> Kav008Hy | AD8: =DATEDIF(H8, TODAY(), "Y") -> 49 | AE8: =IFERROR(IF(OR(E8="", D8="", LOWER(TRIM(E8))="pending", LOWER(TRIM(D8))="pending"), "Pending", E8 - D8), "Pending") -> Pending | AF8: =IFERROR(IF(OR(E8="", D8="","Pending","Pending"), "Pending", IF((E8 - D8) <= 5, "On Time", "Delayed")), "Pending") -> Pending | AG8: =IF(AF8="Pending","Pending","Completed") -> Pending
A9: ORD10008 | B9: C002 | C9: P104 | D9: 45760 | E9: 19/04/2025 | F9: =VLOOKUP(B9,Custumer_Master!A:D,2,FALSE) -> Priya Patel | G9: =VLOOKUP($B9,Custumer_Master!$A:$J,6,FALSE) -> Female | H9: =VLOOKUP($B9,Custumer_Master!$A:$J,7,FALSE) -> 07/03/1995 | I9: =VLOOKUP($B9,Custumer_Master!$A:$J,9,FALSE) -> Mumbai | J9: =VLOOKUP($B9,Custumer_Master!$A:$J,10,FALSE) -> West | K9: =VLOOKUP(B9,Custumer_Master!A:D,4,FALSE) -> WB | L9: =PROPER(TRIM(VLOOKUP('Final Data'!C9,Product_Master!A:F,3,FALSE))) -> Electronics | M9: Monitor | N9: 14 | O9: =VLOOKUP(C9,Product_Master!A:F,5,FALSE) -> 9000 | P9: 0.15 | Q9: =(N9*O9)-(N9*O9)*P9 -> 107100 | R9: 4 | S9: Netbanking | T9: Ritika | U9: priya.patel@company.com | V9: 9705521654 | W9: =VLOOKUP(C9,Product_Master!A:F,4,FALSE) -> Global Trade | X9: =VLOOKUP(C9,Product_Master!A:F,6,FALSE) -> 24 | Y9: =VLOOKUP(B9,Custumer_Master!A:D,3,FALSE) -> Platinum | Z9: =EDATE(E9,X9) -> 46496 | AA9: =VLOOKUP(B9,Custumer_Master!A:K,11,) -> March | AB9: Gold | AC9: =PROPER(LEFT(TRIM(F9), 3)) & RIGHT(TRIM(B9), 3) & PROPER(LEFT(TRIM(I9), 2)) -> Pri002Mu | AD9: =DATEDIF(H9, TODAY(), "Y") -> 31 | AE9: =IFERROR(IF(OR(E9="", D9="", LOWER(TRIM(E9))="pending", LOWER(TRIM(D9))="pending"), "Pending", E9 - D9), "Pending") -> 6 | AF9: =IFERROR(IF(OR(E9="", D9="","Pending","Pending"), "Pending", IF((E9 - D9) <= 5, "On Time", "Delayed")), "Pending") -> Delayed | AG9: =IF(AF9="Pending","Pending","Completed") -> Completed
A10: ORD10009 | B10: C008 | C10: P104 | D10: 46053 | E10: 02/02/2026 | F10: =VLOOKUP(B10,Custumer_Master!A:D,2,FALSE) -> Kavya Nair | G10: =VLOOKUP($B10,Custumer_Master!$A:$J,6,FALSE) -> Female | H10: =VLOOKUP($B10,Custumer_Master!$A:$J,7,FALSE) -> 01/08/1976 | I10: =VLOOKUP($B10,Custumer_Master!$A:$J,9,FALSE) -> Hyderabad | J10: =VLOOKUP($B10,Custumer_Master!$A:$J,10,FALSE) -> South | K10: =VLOOKUP(B10,Custumer_Master!A:D,4,FALSE) -> WB | L10: =PROPER(TRIM(VLOOKUP('Final Data'!C10,Product_Master!A:F,3,FALSE))) -> Electronics | M10: Monitor | N10: 4 | O10: =VLOOKUP(C10,Product_Master!A:F,5,FALSE) -> 9000 | P10: 0.15 | Q10: =(N10*O10)-(N10*O10)*P10 -> 30600 | R10: 4 | S10: Upi | T10: Neha | U10: kavya.nair@company.com | V10: 9588041011 | W10: =VLOOKUP(C10,Product_Master!A:F,4,FALSE) -> Global Trade | X10: =VLOOKUP(C10,Product_Master!A:F,6,FALSE) -> 24 | Y10: =VLOOKUP(B10,Custumer_Master!A:D,3,FALSE) -> Silver | Z10: =EDATE(E10,X10) -> 46785 | AA10: =VLOOKUP(B10,Custumer_Master!A:K,11,) -> August | AB10: Silver | AC10: =PROPER(LEFT(TRIM(F10), 3)) & RIGHT(TRIM(B10), 3) & PROPER(LEFT(TRIM(I10), 2)) -> Kav008Hy | AD10: =DATEDIF(H10, TODAY(), "Y") -> 49 | AE10: =IFERROR(IF(OR(E10="", D10="", LOWER(TRIM(E10))="pending", LOWER(TRIM(D10))="pending"), "Pending", E10 - D10), "Pending") -> 2 | AF10: =IFERROR(IF(OR(E10="", D10="","Pending","Pending"), "Pending", IF((E10 - D10) <= 5, "On Time", "Delayed")), "Pending") -> On Time | AG10: =IF(AF10="Pending","Pending","Completed") -> Completed
A11: ORD10010 | B11: C002 | C11: P301 | D11: 45741 | E11: 27/03/2025 | F11: =VLOOKUP(B11,Custumer_Master!A:D,2,FALSE) -> Priya Patel | G11: =VLOOKUP($B11,Custumer_Master!$A:$J,6,FALSE) -> Female | H11: =VLOOKUP($B11,Custumer_Master!$A:$J,7,FALSE) -> 07/03/1995 | I11: =VLOOKUP($B11,Custumer_Master!$A:$J,9,FALSE) -> Mumbai | J11: =VLOOKUP($B11,Custumer_Master!$A:$J,10,FALSE) -> West | K11: =VLOOKUP(B11,Custumer_Master!A:D,4,FALSE) -> WB | L11: =PROPER(TRIM(VLOOKUP('Final Data'!C11,Product_Master!A:F,3,FALSE))) -> Stationery | M11: Notebook | N11: 6 | O11: =VLOOKUP(C11,Product_Master!A:F,5,FALSE) -> 45 | P11: 0 | Q11: =(N11*O11)-(N11*O11)*P11 -> 270 | R11: 4 | S11: Card | T11: Neha | U11: priya.patel@company.com | V11: 9340540608 | W11: =VLOOKUP(C11,Product_Master!A:F,4,FALSE) -> ABC Corp | X11: =VLOOKUP(C11,Product_Master!A:F,6,FALSE) -> 12 | Y11: =VLOOKUP(B11,Custumer_Master!A:D,3,FALSE) -> Platinum | Z11: =EDATE(E11,X11) -> 46108 | AA11: =VLOOKUP(B11,Custumer_Master!A:K,11,) -> March | AB11: Silver | AC11: =PROPER(LEFT(TRIM(F11), 3)) & RIGHT(TRIM(B11), 3) & PROPER(LEFT(TRIM(I11), 2)) -> Pri002Mu | AD11: =DATEDIF(H11, TODAY(), "Y") -> 31 | AE11: =IFERROR(IF(OR(E11="", D11="", LOWER(TRIM(E11))="pending", LOWER(TRIM(D11))="pending"), "Pending", E11 - D11), "Pending") -> 2 | AF11: =IFERROR(IF(OR(E11="", D11="","Pending","Pending"), "Pending", IF((E11 - D11) <= 5, "On Time", "Delayed")), "Pending") -> On Time | AG11: =IF(AF11="Pending","Pending","Completed") -> Completed
A12: ORD10011 | B12: C003 | C12: P202 | D12: 45919 | E12: 23/09/2025 | F12: =VLOOKUP(B12,Custumer_Master!A:D,2,FALSE) -> Rohit Singh | G12: =VLOOKUP($B12,Custumer_Master!$A:$J,6,FALSE) -> Male | H12: =VLOOKUP($B12,Custumer_Master!$A:$J,7,FALSE) -> 10/05/1982 | I12: =VLOOKUP($B12,Custumer_Master!$A:$J,9,FALSE) -> Delhi | J12: =VLOOKUP($B12,Custumer_Master!$A:$J,10,FALSE) -> North | K12: =VLOOKUP(B12,Custumer_Master!A:D,4,FALSE) -> DL | L12: =PROPER(TRIM(VLOOKUP('Final Data'!C12,Product_Master!A:F,3,FALSE))) -> Home Appliances | M12: Iron | N12: 3 | O12: =VLOOKUP(C12,Product_Master!A:F,5,FALSE) -> 1650 | P12: 0 | Q12: =(N12*O12)-(N12*O12)*P12 -> 4950 | R12: 2 | S12: Card | T12: Rahul | U12: rohit.singh@company.com | V12: 9521710321 | W12: =VLOOKUP(C12,Product_Master!A:F,4,FALSE) -> Global Trade | X12: =VLOOKUP(C12,Product_Master!A:F,6,FALSE) -> 24 | Y12: =VLOOKUP(B12,Custumer_Master!A:D,3,FALSE) -> Gold | Z12: =EDATE(E12,X12) -> 46653 | AA12: =VLOOKUP(B12,Custumer_Master!A:K,11,) -> May | AB12: Blacklisted | AC12: =PROPER(LEFT(TRIM(F12), 3)) & RIGHT(TRIM(B12), 3) & PROPER(LEFT(TRIM(I12), 2)) -> Roh003De | AD12: =DATEDIF(H12, TODAY(), "Y") -> 44 | AE12: =IFERROR(IF(OR(E12="", D12="", LOWER(TRIM(E12))="pending", LOWER(TRIM(D12))="pending"), "Pending", E12 - D12), "Pending") -> 4 | AF12: =IFERROR(IF(OR(E12="", D12="","Pending","Pending"), "Pending", IF((E12 - D12) <= 5, "On Time", "Delayed")), "Pending") -> On Time | AG12: =IF(AF12="Pending","Pending","Completed") -> Completed
A13: ORD10012 | B13: C008 | C13: P201 | D13: 45724 | E13: 15/03/2025 | F13: =VLOOKUP(B13,Custumer_Master!A:D,2,FALSE) -> Kavya Nair | G13: =VLOOKUP($B13,Custumer_Master!$A:$J,6,FALSE) -> Female | H13: =VLOOKUP($B13,Custumer_Master!$A:$J,7,FALSE) -> 01/08/1976 | I13: =VLOOKUP($B13,Custumer_Master!$A:$J,9,FALSE) -> Hyderabad | J13: =VLOOKUP($B13,Custumer_Master!$A:$J,10,FALSE) -> South | K13: =VLOOKUP(B13,Custumer_Master!A:D,4,FALSE) -> WB | L13: =PROPER(TRIM(VLOOKUP('Final Data'!C13,Product_Master!A:F,3,FALSE))) -> Home Appliances | M13: Mixer | N13: 10 | O13: =VLOOKUP(C13,Product_Master!A:F,5,FALSE) -> 2625 | P13: 0.05 | Q13: =(N13*O13)-(N13*O13)*P13 -> 24937.5 | R13: 5 | S13: Card | T13: Aisha | U13: kavya.nair@company.com | V13: 9123535241 | W13: =VLOOKUP(C13,Product_Master!A:F,4,FALSE) -> Global Trade | X13: =VLOOKUP(C13,Product_Master!A:F,6,FALSE) -> 6 | Y13: =VLOOKUP(B13,Custumer_Master!A:D,3,FALSE) -> Silver | Z13: =EDATE(E13,X13) -> 45915 | AA13: =VLOOKUP(B13,Custumer_Master!A:K,11,) -> August | AB13: Silver | AC13: =PROPER(LEFT(TRIM(F13), 3)) & RIGHT(TRIM(B13), 3) & PROPER(LEFT(TRIM(I13), 2)) -> Kav008Hy | AD13: =DATEDIF(H13, TODAY(), "Y") -> 49 | AE13: =IFERROR(IF(OR(E13="", D13="", LOWER(TRIM(E13))="pending", LOWER(TRIM(D13))="pending"), "Pending", E13 - D13), "Pending") -> 7 | AF13: =IFERROR(IF(OR(E13="", D13="","Pending","Pending"), "Pending", IF((E13 - D13) <= 5, "On Time", "Delayed")), "Pending") -> Delayed | AG13: =IF(AF13="Pending","Pending","Completed") -> Completed
A14: ORD10013 | B14: C002 | C14: P202 | D14: 45667 | E14: 15/01/2025 | F14: =VLOOKUP(B14,Custumer_Master!A:D,2,FALSE) -> Priya Patel | G14: =VLOOKUP($B14,Custumer_Master!$A:$J,6,FALSE) -> Female | H14: =VLOOKUP($B14,Custumer_Master!$A:$J,7,FALSE) -> 07/03/1995 | I14: =VLOOKUP($B14,Custumer_Master!$A:$J,9,FALSE) -> Mumbai | J14: =VLOOKUP($B14,Custumer_Master!$A:$J,10,FALSE) -> West | K14: =VLOOKUP(B14,Custumer_Master!A:D,4,FALSE) -> WB | L14: =PROPER(TRIM(VLOOKUP('Final Data'!C14,Product_Master!A:F,3,FALSE))) -> Home Appliances | M14: Iron | N14: 15 | O14: =VLOOKUP(C14,Product_Master!A:F,5,FALSE) -> 1650 | P14: 0.1 | Q14: =(N14*O14)-(N14*O14)*P14 -> 22275 | R14: 1 | S14: Upi | T14: Neha | U14: priya.patel@company.com | V14: 9367316892 | W14: =VLOOKUP(C14,Product_Master!A:F,4,FALSE) -> Global Trade | X14: =VLOOKUP(C14,Product_Master!A:F,6,FALSE) -> 24 | Y14: =VLOOKUP(B14,Custumer_Master!A:D,3,FALSE) -> Platinum | Z14: =EDATE(E14,X14) -> 46402 | AA14: =VLOOKUP(B14,Custumer_Master!A:K,11,) -> March | AB14: Blacklisted | AC14: =PROPER(LEFT(TRIM(F14), 3)) & RIGHT(TRIM(B14), 3) & PROPER(LEFT(TRIM(I14), 2)) -> Pri002Mu | AD14: =DATEDIF(H14, TODAY(), "Y") -> 31 | AE14: =IFERROR(IF(OR(E14="", D14="", LOWER(TRIM(E14))="pending", LOWER(TRIM(D14))="pending"), "Pending", E14 - D14), "Pending") -> 5 | AF14: =IFERROR(IF(OR(E14="", D14="","Pending","Pending"), "Pending", IF((E14 - D14) <= 5, "On Time", "Delayed")), "Pending") -> On Time | AG14: =IF(AF14="Pending","Pending","Completed") -> Completed
A15: ORD10014 | B15: C003 | C15: P202 | D15: 45725 | E15: 13/03/2025 | F15: =VLOOKUP(B15,Custumer_Master!A:D,2,FALSE) -> Rohit Singh | G15: =VLOOKUP($B15,Custumer_Master!$A:$J,6,FALSE) -> Male | H15: =VLOOKUP($B15,Custumer_Master!$A:$J,7,FALSE) -> 10/05/1982 | I15: =VLOOKUP($B15,Custumer_Master!$A:$J,9,FALSE) -> Delhi | J15: =VLOOKUP($B15,Custumer_Master!$A:$J,10,FALSE) -> North | K15: =VLOOKUP(B15,Custumer_Master!A:D,4,FALSE) -> DL | L15: =PROPER(TRIM(VLOOKUP('Final Data'!C15,Product_Master!A:F,3,FALSE))) -> Home Appliances | M15: Iron | N15: 17 | O15: =VLOOKUP(C15,Product_Master!A:F,5,FALSE) -> 1650 | P15: 0.05 | Q15: =(N15*O15)-(N15*O15)*P15 -> 26647.5 | R15: 1 | S15: Cash | T15: Karan | U15: rohit.singh@company.com | V15: 9778489803 | W15: =VLOOKUP(C15,Product_Master!A:F,4,FALSE) -> Global Trade | X15: =VLOOKUP(C15,Product_Master!A:F,6,FALSE) -> 24 | Y15: =VLOOKUP(B15,Custumer_Master!A:D,3,FALSE) -> Gold | Z15: =EDATE(E15,X15) -> 46459 | AA15: =VLOOKUP(B15,Custumer_Master!A:K,11,) -> May | AB15: Blacklisted | AC15: =PROPER(LEFT(TRIM(F15), 3)) & RIGHT(TRIM(B15), 3) & PROPER(LEFT(TRIM(I15), 2)) -> Roh003De | AD15: =DATEDIF(H15, TODAY(), "Y") -> 44 | AE15: =IFERROR(IF(OR(E15="", D15="", LOWER(TRIM(E15))="pending", LOWER(TRIM(D15))="pending"), "Pending", E15 - D15), "Pending") -> 4 | AF15: =IFERROR(IF(OR(E15="", D15="","Pending","Pending"), "Pending", IF((E15 - D15) <= 5, "On Time", "Delayed")), "Pending") -> On Time | AG15: =IF(AF15="Pending","Pending","Completed") -> Completed
A16: ORD10015 | B16: C008 | C16: P201 | D16: 45864 | E16: 07/08/2025 | F16: =VLOOKUP(B16,Custumer_Master!A:D,2,FALSE) -> Kavya Nair | G16: =VLOOKUP($B16,Custumer_Master!$A:$J,6,FALSE) -> Female | H16: =VLOOKUP($B16,Custumer_Master!$A:$J,7,FALSE) -> 01/08/1976 | I16: =VLOOKUP($B16,Custumer_Master!$A:$J,9,FALSE) -> Hyderabad | J16: =VLOOKUP($B16,Custumer_Master!$A:$J,10,FALSE) -> South | K16: =VLOOKUP(B16,Custumer_Master!A:D,4,FALSE) -> WB | L16: =PROPER(TRIM(VLOOKUP('Final Data'!C16,Product_Master!A:F,3,FALSE))) -> Home Appliances | M16: Mixer | N16: 15 | O16: =VLOOKUP(C16,Product_Master!A:F,5,FALSE) -> 2625 | P16: 0.15 | Q16: =(N16*O16)-(N16*O16)*P16 -> 33468.75 | R16: 2 | S16: Cash | T16: Neha | U16: kavya.nair@company.com | V16: 9582960180 | W16: =VLOOKUP(C16,Product_Master!A:F,4,FALSE) -> Global Trade | X16: =VLOOKUP(C16,Product_Master!A:F,6,FALSE) -> 6 | Y16: =VLOOKUP(B16,Custumer_Master!A:D,3,FALSE) -> Silver | Z16: =EDATE(E16,X16) -> 46060 | AA16: =VLOOKUP(B16,Custumer_Master!A:K,11,) -> August | AB16: Blacklisted | AC16: =PROPER(LEFT(TRIM(F16), 3)) & RIGHT(TRIM(B16), 3) & PROPER(LEFT(TRIM(I16), 2)) -> Kav008Hy | AD16: =DATEDIF(H16, TODAY(), "Y") -> 49 | AE16: =IFERROR(IF(OR(E16="", D16="", LOWER(TRIM(E16))="pending", LOWER(TRIM(D16))="pending"), "Pending", E16 - D16), "Pending") -> 12 | AF16: =IFERROR(IF(OR(E16="", D16="","Pending","Pending"), "Pending", IF((E16 - D16) <= 5, "On Time", "Delayed")), "Pending") -> Delayed | AG16: =IF(AF16="Pending","Pending","Completed") -> Completed
A17: ORD10016 | B17: C010 | C17: P103 | D17: 46120 | E17: 11/04/2026 | F17: =VLOOKUP(B17,Custumer_Master!A:D,2,FALSE) -> Pooja Shah | G17: =VLOOKUP($B17,Custumer_Master!$A:$J,6,FALSE) -> Female | H17: =VLOOKUP($B17,Custumer_Master!$A:$J,7,FALSE) -> 16/09/1994 | I17: =VLOOKUP($B17,Custumer_Master!$A:$J,9,FALSE) -> Bengaluru | J17: =VLOOKUP($B17,Custumer_Master!$A:$J,10,FALSE) -> South | K17: =VLOOKUP(B17,Custumer_Master!A:D,4,FALSE) -> WB | L17: =PROPER(TRIM(VLOOKUP('Final Data'!C17,Product_Master!A:F,3,FALSE))) -> Electronics | M17: Keyboard | N17: 3 | O17: =VLOOKUP(C17,Product_Master!A:F,5,FALSE) -> 900 | P17: 0.05 | Q17: =(N17*O17)-(N17*O17)*P17 -> 2565 | R17: 5 | S17: Upi | T17: Ritika | U17: pooja.shah@company.com | V17: 9611394005 | W17: =VLOOKUP(C17,Product_Master!A:F,4,FALSE) -> TechHub | X17: =VLOOKUP(C17,Product_Master!A:F,6,FALSE) -> 6 | Y17: =VLOOKUP(B17,Custumer_Master!A:D,3,FALSE) -> Silver | Z17: =EDATE(E17,X17) -> 46306 | AA17: =VLOOKUP(B17,Custumer_Master!A:K,11,) -> September | AB17: Silver | AC17: =PROPER(LEFT(TRIM(F17), 3)) & RIGHT(TRIM(B17), 3) & PROPER(LEFT(TRIM(I17), 2)) -> Poo010Be | AD17: =DATEDIF(H17, TODAY(), "Y") -> 31 | AE17: =IFERROR(IF(OR(E17="", D17="", LOWER(TRIM(E17))="pending", LOWER(TRIM(D17))="pending"), "Pending", E17 - D17), "Pending") -> 3 | AF17: =IFERROR(IF(OR(E17="", D17="","Pending","Pending"), "Pending", IF((E17 - D17) <= 5, "On Time", "Delayed")), "Pending") -> On Time | AG17: =IF(AF17="Pending","Pending","Completed") -> Completed
A18: ORD10017 | B18: C004 | C18: P203 | D18: 46075 | E18: 03/03/2026 | F18: =VLOOKUP(B18,Custumer_Master!A:D,2,FALSE) -> Anita Gupta | G18: =VLOOKUP($B18,Custumer_Master!$A:$J,6,FALSE) -> Female | H18: =VLOOKUP($B18,Custumer_Master!$A:$J,7,FALSE) -> 16/01/2002 | I18: =VLOOKUP($B18,Custumer_Master!$A:$J,9,FALSE) -> Pune | J18: =VLOOKUP($B18,Custumer_Master!$A:$J,10,FALSE) -> West | K18: =VLOOKUP(B18,Custumer_Master!A:D,4,FALSE) -> WB | L18: =PROPER(TRIM(VLOOKUP('Final Data'!C18,Product_Master!A:F,3,FALSE))) -> Home Appliances | M18: Microwave | N18: 13 | O18: =VLOOKUP(C18,Product_Master!A:F,5,FALSE) -> 6375 | P18: 0.2 | Q18: =(N18*O18)-(N18*O18)*P18 -> 66300 | R18: 4 | S18: Card | T18: Rahul | U18: anita.gupta@company.com | V18: 9692599404 | W18: =VLOOKUP(C18,Product_Master!A:F,4,FALSE) -> TechHub | X18: =VLOOKUP(C18,Product_Master!A:F,6,FALSE) -> 24 | Y18: =VLOOKUP(B18,Custumer_Master!A:D,3,FALSE) -> Gold | Z18: =EDATE(E18,X18) -> 46815 | AA18: =VLOOKUP(B18,Custumer_Master!A:K,11,) -> January | AB18: Gold | AC18: =PROPER(LEFT(TRIM(F18), 3)) & RIGHT(TRIM(B18), 3) & PROPER(LEFT(TRIM(I18), 2)) -> Ani004Pu | AD18: =DATEDIF(H18, TODAY(), "Y") -> 24 | AE18: =IFERROR(IF(OR(E18="", D18="", LOWER(TRIM(E18))="pending", LOWER(TRIM(D18))="pending"), "Pending", E18 - D18), "Pending") -> 9 | AF18: =IFERROR(IF(OR(E18="", D18="","Pending","Pending"), "Pending", IF((E18 - D18) <= 5, "On Time", "Delayed")), "Pending") -> Delayed | AG18: =IF(AF18="Pending","Pending","Completed") -> Completed
A19: ORD10018 | B19: C007 | C19: P203 | D19: 46081 | E19: 05/03/2026 | F19: =VLOOKUP(B19,Custumer_Master!A:D,2,FALSE) -> Arjun Rao | G19: =VLOOKUP($B19,Custumer_Master!$A:$J,6,FALSE) -> Male | H19: =VLOOKUP($B19,Custumer_Master!$A:$J,7,FALSE) -> 07/02/1988 | I19: =VLOOKUP($B19,Custumer_Master!$A:$J,9,FALSE) -> Hyderabad | J19: =VLOOKUP($B19,Custumer_Master!$A:$J,10,FALSE) -> South | K19: =VLOOKUP(B19,Custumer_Master!A:D,4,FALSE) -> RJ | L19: =PROPER(TRIM(VLOOKUP('Final Data'!C19,Product_Master!A:F,3,FALSE))) -> Home Appliances | M19: Microwave | N19: 4 | O19: =VLOOKUP(C19,Product_Master!A:F,5,FALSE) -> 6375 | P19: 0.2 | Q19: =(N19*O19)-(N19*O19)*P19 -> 20400 | R19: 5 | S19: Card | T19: Aisha | U19: arjun.rao@company.com | V19: 9426119622 | W19: =VLOOKUP(C19,Product_Master!A:F,4,FALSE) -> TechHub | X19: =VLOOKUP(C19,Product_Master!A:F,6,FALSE) -> 24 | Y19: =VLOOKUP(B19,Custumer_Master!A:D,3,FALSE) -> Silver | Z19: =EDATE(E19,X19) -> 46817 | AA19: =VLOOKUP(B19,Custumer_Master!A:K,11,) -> February | AB19: Silver | AC19: =PROPER(LEFT(TRIM(F19), 3)) & RIGHT(TRIM(B19), 3) & PROPER(LEFT(TRIM(I19), 2)) -> Arj007Hy | AD19: =DATEDIF(H19, TODAY(), "Y") -> 38 | AE19: =IFERROR(IF(OR(E19="", D19="", LOWER(TRIM(E19))="pending", LOWER(TRIM(D19))="pending"), "Pending", E19 - D19), "Pending") -> 5 | AF19: =IFERROR(IF(OR(E19="", D19="","Pending","Pending"), "Pending", IF((E19 - D19) <= 5, "On Time", "Delayed")), "Pending") -> On Time | AG19: =IF(AF19="Pending","Pending","Completed") -> Completed
A20: ORD10019 | B20: C007 | C20: P102 | D20: 45992 | E20: 04/12/2025 | F20: =VLOOKUP(B20,Custumer_Master!A:D,2,FALSE) -> Arjun Rao | G20: =VLOOKUP($B20,Custumer_Master!$A:$J,6,FALSE) -> Male | H20: =VLOOKUP($B20,Custumer_Master!$A:$J,7,FALSE) -> 07/02/1988 | I20: =VLOOKUP($B20,Custumer_Master!$A:$J,9,FALSE) -> Hyderabad | J20: =VLOOKUP($B20,Custumer_Master!$A:$J,10,FALSE) -> South | K20: =VLOOKUP(B20,Custumer_Master!A:D,4,FALSE) -> RJ | L20: =PROPER(TRIM(VLOOKUP('Final Data'!C20,Product_Master!A:F,3,FALSE))) -> Electronics | M20: Mouse | N20: 9 | O20: =VLOOKUP(C20,Product_Master!A:F,5,FALSE) -> 525 | P20: 0.05 | Q20: =(N20*O20)-(N20*O20)*P20 -> 4488.75 | R20: 3 | S20: Upi | T20: Ritika | U20: arjun.rao@company.com | V20: 9184436009 | W20: =VLOOKUP(C20,Product_Master!A:F,4,FALSE) -> TechHub | X20: =VLOOKUP(C20,Product_Master!A:F,6,FALSE) -> 24 | Y20: =VLOOKUP(B20,Custumer_Master!A:D,3,FALSE) -> Silver | Z20: =EDATE(E20,X20) -> 46725 | AA20: =VLOOKUP(B20,Custumer_Master!A:K,11,) -> February | AB20: Silver | AC20: =PROPER(LEFT(TRIM(F20), 3)) & RIGHT(TRIM(B20), 3) & PROPER(LEFT(TRIM(I20), 2)) -> Arj007Hy | AD20: =DATEDIF(H20, TODAY(), "Y") -> 38 | AE20: =IFERROR(IF(OR(E20="", D20="", LOWER(TRIM(E20))="pending", LOWER(TRIM(D20))="pending"), "Pending", E20 - D20), "Pending") -> 3 | AF20: =IFERROR(IF(OR(E20="", D20="","Pending","Pending"), "Pending", IF((E20 - D20) <= 5, "On Time", "Delayed")), "Pending") -> On Time | AG20: =IF(AF20="Pending","Pending","Completed") -> Completed
... A49: ORD10048 | B49: C006 | C49: P102 | D49: 45988 | E49: 03/12/2025 | F49: =VLOOKUP(B49,Custumer_Master!A:D,2,FALSE) -> Sneha Joshi | G49: =VLOOKUP($B49,Custumer_Master!$A:$J,6,FALSE) -> Female | H49: =VLOOKUP($B49,Custumer_Master!$A:$J,7,FALSE) -> 04/04/1981 | I49: =VLOOKUP($B49,Custumer_Master!$A:$J,9,FALSE) -> Pune | J49: =VLOOKUP($B49,Custumer_Master!$A:$J,10,FALSE) -> West | K49: =VLOOKUP(B49,Custumer_Master!A:D,4,FALSE) -> WB | L49: =PROPER(TRIM(VLOOKUP('Final Data'!C49,Product_Master!A:F,3,FALSE))) -> Electronics | M49: Mouse | N49: 19 | O49: =VLOOKUP(C49,Product_Master!A:F,5,FALSE) -> 525 | P49: 0.2 | Q49: =(N49*O49)-(N49*O49)*P49 -> 7980 | R49: 1 | S49: Cash | T49: Neha | U49: sneha.joshi@company.com | V49: 9238141322 | W49: =VLOOKUP(C49,Product_Master!A:F,4,FALSE) -> TechHub | X49: =VLOOKUP(C49,Product_Master!A:F,6,FALSE) -> 24 | Y49: =VLOOKUP(B49,Custumer_Master!A:D,3,FALSE) -> Gold | Z49: =EDATE(E49,X49) -> 46724 | AA49: =VLOOKUP(B49,Custumer_Master!A:K,11,) -> April | AB49: Blacklisted | AC49: =PROPER(LEFT(TRIM(F49), 3)) & RIGHT(TRIM(B49), 3) & PROPER(LEFT(TRIM(I49), 2)) -> Sne006Pu | AD49: =DATEDIF(H49, TODAY(), "Y") -> 45 | AE49: =IFERROR(IF(OR(E49="", D49="", LOWER(TRIM(E49))="pending", LOWER(TRIM(D49))="pending"), "Pending", E49 - D49), "Pending") -> 6 | AF49: =IFERROR(IF(OR(E49="", D49="","Pending","Pending"), "Pending", IF((E49 - D49) <= 5, "On Time", "Delayed")), "Pending") -> Delayed | AG49: =IF(AF49="Pending","Pending","Completed") -> Completed
A50: ORD10049 | B50: C009 | C50: P104 | D50: 46131 | F50: =VLOOKUP(B50,Custumer_Master!A:D,2,FALSE) -> Mohit Verma | G50: =VLOOKUP($B50,Custumer_Master!$A:$J,6,FALSE) -> Male | H50: =VLOOKUP($B50,Custumer_Master!$A:$J,7,FALSE) -> 13/04/1976 | I50: =VLOOKUP($B50,Custumer_Master!$A:$J,9,FALSE) -> Delhi | J50: =VLOOKUP($B50,Custumer_Master!$A:$J,10,FALSE) -> North | K50: =VLOOKUP(B50,Custumer_Master!A:D,4,FALSE) -> KA | L50: =PROPER(TRIM(VLOOKUP('Final Data'!C50,Product_Master!A:F,3,FALSE))) -> Electronics | M50: Monitor | N50: 19 | O50: =VLOOKUP(C50,Product_Master!A:F,5,FALSE) -> 9000 | P50: 0 | Q50: =(N50*O50)-(N50*O50)*P50 -> 171000 | R50: 1 | S50: Netbanking | T50: Aisha | U50: mohit.verma@company.com | V50: 9890380030 | W50: =VLOOKUP(C50,Product_Master!A:F,4,FALSE) -> Global Trade | X50: =VLOOKUP(C50,Product_Master!A:F,6,FALSE) -> 24 | Y50: =VLOOKUP(B50,Custumer_Master!A:D,3,FALSE) -> Platinum | Z50: =EDATE(E50,X50) -> 731 | AA50: =VLOOKUP(B50,Custumer_Master!A:K,11,) -> April | AB50: Blacklisted | AC50: =PROPER(LEFT(TRIM(F50), 3)) & RIGHT(TRIM(B50), 3) & PROPER(LEFT(TRIM(I50), 2)) -> Moh009De | AD50: =DATEDIF(H50, TODAY(), "Y") -> 50 | AE50: =IFERROR(IF(OR(E50="", D50="", LOWER(TRIM(E50))="pending", LOWER(TRIM(D50))="pending"), "Pending", E50 - D50), "Pending") -> Pending | AF50: =IFERROR(IF(OR(E50="", D50="","Pending","Pending"), "Pending", IF((E50 - D50) <= 5, "On Time", "Delayed")), "Pending") -> Pending | AG50: =IF(AF50="Pending","Pending","Completed") -> Pending
A51: ORD10050 | B51: C004 | C51: P103 | D51: 46131 | E51: 21/04/2026 | F51: =VLOOKUP(B51,Custumer_Master!A:D,2,FALSE) -> Anita Gupta | G51: =VLOOKUP($B51,Custumer_Master!$A:$J,6,FALSE) -> Female | H51: =VLOOKUP($B51,Custumer_Master!$A:$J,7,FALSE) -> 16/01/2002 | I51: =VLOOKUP($B51,Custumer_Master!$A:$J,9,FALSE) -> Pune | J51: =VLOOKUP($B51,Custumer_Master!$A:$J,10,FALSE) -> West | K51: =VLOOKUP(B51,Custumer_Master!A:D,4,FALSE) -> WB | L51: =PROPER(TRIM(VLOOKUP('Final Data'!C51,Product_Master!A:F,3,FALSE))) -> Electronics | M51: Keyboard | N51: 6 | O51: =VLOOKUP(C51,Product_Master!A:F,5,FALSE) -> 900 | P51: 0.05 | Q51: =(N51*O51)-(N51*O51)*P51 -> 5130 | R51: 2 | S51: Cash | T51: Ritika | U51: anita.gupta@company.com | V51: 9495893170 | W51: =VLOOKUP(C51,Product_Master!A:F,4,FALSE) -> TechHub | X51: =VLOOKUP(C51,Product_Master!A:F,6,FALSE) -> 6 | Y51: =VLOOKUP(B51,Custumer_Master!A:D,3,FALSE) -> Gold | Z51: =EDATE(E51,X51) -> 46316 | AA51: =VLOOKUP(B51,Custumer_Master!A:K,11,) -> January | AB51: Blacklisted | AC51: =PROPER(LEFT(TRIM(F51), 3)) & RIGHT(TRIM(B51), 3) & PROPER(LEFT(TRIM(I51), 2)) -> Ani004Pu | AD51: =DATEDIF(H51, TODAY(), "Y") -> 24 | AE51: =IFERROR(IF(OR(E51="", D51="", LOWER(TRIM(E51))="pending", LOWER(TRIM(D51))="pending"), "Pending", E51 - D51), "Pending") -> 2 | AF51: =IFERROR(IF(OR(E51="", D51="","Pending","Pending"), "Pending", IF((E51 - D51) <= 5, "On Time", "Delayed")), "Pending") -> On Time | AG51: =IF(AF51="Pending","Pending","Completed") -> Completed
A52: ORD10051 | B52: C010 | C52: P202 | D52: 45744 | E52: 07/04/2025 | F52: =VLOOKUP(B52,Custumer_Master!A:D,2,FALSE) -> Pooja Shah | G52: =VLOOKUP($B52,Custumer_Master!$A:$J,6,FALSE) -> Female | H52: =VLOOKUP($B52,Custumer_Master!$A:$J,7,FALSE) -> 16/09/1994 | I52: =VLOOKUP($B52,Custumer_Master!$A:$J,9,FALSE) -> Bengaluru | J52: =VLOOKUP($B52,Custumer_Master!$A:$J,10,FALSE) -> South | K52: =VLOOKUP(B52,Custumer_Master!A:D,4,FALSE) -> WB | L52: =PROPER(TRIM(VLOOKUP('Final Data'!C52,Product_Master!A:F,3,FALSE))) -> Home Appliances | M52: Iron | N52: 7 | O52: =VLOOKUP(C52,Product_Master!A:F,5,FALSE) -> 1650 | P52: 0.15 | Q52: =(N52*O52)-(N52*O52)*P52 -> 9817.5 | R52: 1 | S52: Upi | T52: Aisha | U52: pooja.shah@company.com | V52: 9485166307 | W52: =VLOOKUP(C52,Product_Master!A:F,4,FALSE) -> Global Trade | X52: =VLOOKUP(C52,Product_Master!A:F,6,FALSE) -> 24 | Y52: =VLOOKUP(B52,Custumer_Master!A:D,3,FALSE) -> Silver | Z52: =EDATE(E52,X52) -> 46484 | AA52: =VLOOKUP(B52,Custumer_Master!A:K,11,) -> September | AB52: Blacklisted | AC52: =PROPER(LEFT(TRIM(F52), 3)) & RIGHT(TRIM(B52), 3) & PROPER(LEFT(TRIM(I52), 2)) -> Poo010Be | AD52: =DATEDIF(H52, TODAY(), "Y") -> 31 | AE52: =IFERROR(IF(OR(E52="", D52="", LOWER(TRIM(E52))="pending", LOWER(TRIM(D52))="pending"), "Pending", E52 - D52), "Pending") -> 10 | AF52: =IFERROR(IF(OR(E52="", D52="","Pending","Pending"), "Pending", IF((E52 - D52) <= 5, "On Time", "Delayed")), "Pending") -> Delayed | AG52: =IF(AF52="Pending","Pending","Completed") -> Completed
A53: ORD10052 | B53: C002 | C53: P301 | D53: 45894 | E53: 28/08/2025 | F53: =VLOOKUP(B53,Custumer_Master!A:D,2,FALSE) -> Priya Patel | G53: =VLOOKUP($B53,Custumer_Master!$A:$J,6,FALSE) -> Female | H53: =VLOOKUP($B53,Custumer_Master!$A:$J,7,FALSE) -> 07/03/1995 | I53: =VLOOKUP($B53,Custumer_Master!$A:$J,9,FALSE) -> Mumbai | J53: =VLOOKUP($B53,Custumer_Master!$A:$J,10,FALSE) -> West | K53: =VLOOKUP(B53,Custumer_Master!A:D,4,FALSE) -> WB | L53: =PROPER(TRIM(VLOOKUP('Final Data'!C53,Product_Master!A:F,3,FALSE))) -> Stationery | M53: Notebook | N53: 8 | O53: =VLOOKUP(C53,Product_Master!A:F,5,FALSE) -> 45 | P53: 0.1 | Q53: =(N53*O53)-(N53*O53)*P53 -> 324 | R53: 5 | S53: Card | T53: Aisha | U53: priya.patel@company.com | V53: 9924709648 | W53: =VLOOKUP(C53,Product_Master!A:F,4,FALSE) -> ABC Corp | X53: =VLOOKUP(C53,Product_Master!A:F,6,FALSE) -> 12 | Y53: =VLOOKUP(B53,Custumer_Master!A:D,3,FALSE) -> Platinum | Z53: =EDATE(E53,X53) -> 46262 | AA53: =VLOOKUP(B53,Custumer_Master!A:K,11,) -> March | AB53: Silver | AC53: =PROPER(LEFT(TRIM(F53), 3)) & RIGHT(TRIM(B53), 3) & PROPER(LEFT(TRIM(I53), 2)) -> Pri002Mu | AD53: =DATEDIF(H53, TODAY(), "Y") -> 31 | AE53: =IFERROR(IF(OR(E53="", D53="", LOWER(TRIM(E53))="pending", LOWER(TRIM(D53))="pending"), "Pending", E53 - D53), "Pending") -> 3 | AF53: =IFERROR(IF(OR(E53="", D53="","Pending","Pending"), "Pending", IF((E53 - D53) <= 5, "On Time", "Delayed")), "Pending") -> On Time | AG53: =IF(AF53="Pending","Pending","Completed") -> Completed
A54: ORD10053 | B54: C005 | C54: P101 | D54: 45888 | E54: 23/08/2025 | F54: =VLOOKUP(B54,Custumer_Master!A:D,2,FALSE) -> Vikas Mehta | G54: =VLOOKUP($B54,Custumer_Master!$A:$J,6,FALSE) -> Male | H54: =VLOOKUP($B54,Custumer_Master!$A:$J,7,FALSE) -> 03/08/1991 | I54: =VLOOKUP($B54,Custumer_Master!$A:$J,9,FALSE) -> Mumbai | J54: =VLOOKUP($B54,Custumer_Master!$A:$J,10,FALSE) -> West | K54: =VLOOKUP(B54,Custumer_Master!A:D,4,FALSE) -> DL | L54: =PROPER(TRIM(VLOOKUP('Final Data'!C54,Product_Master!A:F,3,FALSE))) -> Electronics | M54: Laptop | N54: 12 | O54: =VLOOKUP(C54,Product_Master!A:F,5,FALSE) -> 41250 | P54: 0.05 | Q54: =(N54*O54)-(N54*O54)*P54 -> 470250 | R54: 2 | S54: Upi | T54: Rahul | U54: vikas.mehta@company.com | V54: 9350554626 | W54: =VLOOKUP(C54,Product_Master!A:F,4,FALSE) -> TechHub | X54: =VLOOKUP(C54,Product_Master!A:F,6,FALSE) -> 12 | Y54: =VLOOKUP(B54,Custumer_Master!A:D,3,FALSE) -> Gold | Z54: =EDATE(E54,X54) -> 46257 | AA54: =VLOOKUP(B54,Custumer_Master!A:K,11,) -> August | AB54: Blacklisted | AC54: =PROPER(LEFT(TRIM(F54), 3)) & RIGHT(TRIM(B54), 3) & PROPER(LEFT(TRIM(I54), 2)) -> Vik005Mu | AD54: =DATEDIF(H54, TODAY(), "Y") -> 34 | AE54: =IFERROR(IF(OR(E54="", D54="", LOWER(TRIM(E54))="pending", LOWER(TRIM(D54))="pending"), "Pending", E54 - D54), "Pending") -> 4 | AF54: =IFERROR(IF(OR(E54="", D54="","Pending","Pending"), "Pending", IF((E54 - D54) <= 5, "On Time", "Delayed")), "Pending") -> On Time | AG54: =IF(AF54="Pending","Pending","Completed") -> Completed
A55: ORD10054 | B55: C008 | C55: P102 | D55: 45865 | E55: 05/08/2025 | F55: =VLOOKUP(B55,Custumer_Master!A:D,2,FALSE) -> Kavya Nair | G55: =VLOOKUP($B55,Custumer_Master!$A:$J,6,FALSE) -> Female | H55: =VLOOKUP($B55,Custumer_Master!$A:$J,7,FALSE) -> 01/08/1976 | I55: =VLOOKUP($B55,Custumer_Master!$A:$J,9,FALSE) -> Hyderabad | J55: =VLOOKUP($B55,Custumer_Master!$A:$J,10,FALSE) -> South | K55: =VLOOKUP(B55,Custumer_Master!A:D,4,FALSE) -> WB | L55: =PROPER(TRIM(VLOOKUP('Final Data'!C55,Product_Master!A:F,3,FALSE))) -> Electronics | M55: Mouse | N55: 3 | O55: =VLOOKUP(C55,Product_Master!A:F,5,FALSE) -> 525 | P55: 0 | Q55: =(N55*O55)-(N55*O55)*P55 -> 1575 | R55: 3 | S55: Card | T55: Karan | U55: kavya.nair@company.com | V55: 9743295580 | W55: =VLOOKUP(C55,Product_Master!A:F,4,FALSE) -> TechHub | X55: =VLOOKUP(C55,Product_Master!A:F,6,FALSE) -> 24 | Y55: =VLOOKUP(B55,Custumer_Master!A:D,3,FALSE) -> Silver | Z55: =EDATE(E55,X55) -> 46604 | AA55: =VLOOKUP(B55,Custumer_Master!A:K,11,) -> August | AB55: Silver | AC55: =PROPER(LEFT(TRIM(F55), 3)) & RIGHT(TRIM(B55), 3) & PROPER(LEFT(TRIM(I55), 2)) -> Kav008Hy | AD55: =DATEDIF(H55, TODAY(), "Y") -> 49 | AE55: =IFERROR(IF(OR(E55="", D55="", LOWER(TRIM(E55))="pending", LOWER(TRIM(D55))="pending"), "Pending", E55 - D55), "Pending") -> 9 | AF55: =IFERROR(IF(OR(E55="", D55="","Pending","Pending"), "Pending", IF((E55 - D55) <= 5, "On Time", "Delayed")), "Pending") -> Delayed | AG55: =IF(AF55="Pending","Pending","Completed") -> Completed
